<?xml version="1.0"?>

<robot name="rover">
 <material name="blue">
    <color rgba="0 0 0.8 1"/>
  </material>
  <material name="black">
    <color rgba="0 0 0 1"/>
    <texture filename =""/>
  </material>
  <material name="white">
    <color rgba="1 1 1 1"/>
  </material>
  <material name="red">
    <color rgba="1 0 0 1"/>
  </material>
  <link name="base_footprint">
    <!-- <visual>
      <geometry>
         <box size="0.01 0.01 0.01"/>
      </geometry>
      <material name="white"/>
    </visual> -->
  </link>

  <!-- Body-->
  <link name="base_link">
    <visual>
      <geometry>
         <box size="0.8 0.7 0.1"/>
      </geometry>
      <material name="blue"/>
    </visual>
    <collision>
      <origin xyz="0.0 0.0 0.0" rpy="0.0 0.0 0.0"/>
      <geometry>
        <box size="0.8 0.7 0.1"/>
      </geometry>
    </collision>
  </link>
 <joint name="base_joint" type="fixed">
    <parent link="base_footprint"/>
    <child link="base_link"/>
    <origin rpy="0 0 0" xyz="0.0 0.0 0.135" />
    <axis xyz="0.0 0.0 0.0"/>
  </joint>

  <!-- Front Right Wheel -->
  <link name="front_right_wheel">
    <visual>
      <geometry>
         <cylinder radius="0.15" length="0.1"/>
      </geometry>
      <material name="black"/>
    </visual>
    <collision>
      <origin xyz="0.0 0.0 0.0" rpy="0.0 0.0 0.0"/>
      <geometry>
         <cylinder radius="0.15" length="0.1"/>
      </geometry>
    </collision>
  </link>
  <joint name="front_right_wheel_joint" type="continuous">
      <parent link="base_link"/>
      <child link="front_right_wheel"/>
      <origin rpy="1.57 0 0" xyz="-0.25 0.4 0.0"/>
      <axis xyz="0.0 0.0 1.0"/>
      
  </joint>
  <!-- Front Left Wheel -->
  <link name="front_left_wheel">
    <visual>
      <geometry>
        <cylinder radius="0.15" length="0.1"/>
      </geometry>
      <material name="black"/>
    </visual>
    <collision>
      <origin xyz="0.0 0.0 0.0" rpy="0.0 0.0 0.0"/>
      <geometry>
         <cylinder radius="0.15" length="0.1"/>
      </geometry>
    </collision>
  </link>
  <joint name="front_left_wheel_joint" type="continuous">
    <parent link="base_link"/>
    <child link="front_left_wheel"/>
    <origin rpy="1.57 0 0" xyz="-0.25 -0.4 0.0"/>
    <axis xyz="0.0 0.0 1.0"/>
  </joint>

  <!-- Rear Right Wheel -->
  <link name="rear_right_wheel">
    <visual>
      <geometry>
         <cylinder radius="0.15" length="0.1"/>
      </geometry>
      <material name="black"/>
    </visual>
    <collision>
      <origin xyz="0.0 0.0 0.0" rpy="0.0 0.0 0.0"/>
      <geometry>
         <cylinder radius="0.15" length="0.1"/>
      </geometry>
    </collision>
  </link>
  <joint name="rear_right_wheel_joint" type="continuous">
      <parent link="base_link"/>
      <child link="rear_right_wheel"/>
      <origin rpy="1.57 0 0" xyz="0.25 0.4 0.0"/>
      <axis xyz="0.0 0.0 1.0"/>
  </joint>
  <!-- Rear Left Wheel -->
  <link name="rear_left_wheel">
    <visual>
      <geometry>
        <cylinder radius="0.15" length="0.1"/>
      </geometry>
      <material name="black"/>
    </visual>
    <collision>
      <origin xyz="0.0 0.0 0.0" rpy="0.0 0.0 0.0"/>
      <geometry>
         <cylinder radius="0.15" length="0.1"/>
      </geometry>
    </collision>
  </link>
  <joint name="rear_left_wheel_joint" type="continuous">
    <parent link="base_link"/>
    <child link="rear_left_wheel"/>
    <origin rpy="1.57 0 0" xyz="0.25 -0.4 0.0"/>
    <axis xyz="0.0 0.0 1.0"/>
  </joint>



</robot>